Workbook

Sheet January
A1: TERRANCE MASSEY - January 2026
A3: Week: Dec 29 - Jan 04
A4: Day | B4: Date | C4: Hours | D4: Daily Earnings | E4: Daily Goal | F4: Difference +/- | G4: Status
A5: Monday | B5: 12/29/2025 | C5: 7.04 | D5: 184.67 | E5: 150 | F5: =IF(D5="","",D5-E5) -> 34.67 | G5: =IF(F5="","",IF(F5>=0,"Goal Met","Below Goal")) -> Goal Met
A6: Tuesday | B6: 12/30/2025 | C6: 6.27 | D6: 170.33 | E6: 150 | F6: =IF(D6="","",D6-E6) -> 20.33 | G6: =IF(F6="","",IF(F6>=0,"Goal Met","Below Goal")) -> Goal Met
A7: Wednesday | B7: 12/31/2025 | C7: 10.08 | D7: 314.17 | E7: 150 | F7: =IF(D7="","",D7-E7) -> 164.17 | G7: =IF(F7="","",IF(F7>=0,"Goal Met","Below Goal")) -> Goal Met
A8: Thursday | B8: 1/1/2026 | C8: 6.43 | D8: 190.95 | E8: 150 | F8: =IF(D8="","",D8-E8) -> 40.95 | G8: =IF(F8="","",IF(F8>=0,"Goal Met","Below Goal")) -> Goal Met
A9: Friday | B9: 1/2/2026 | C9: 4.18 | D9: 86.33 | E9: 150 | F9: =IF(D9="","",D9-E9) -> -63.67 | G9: =IF(F9="","",IF(F9>=0,"Goal Met","Below Goal")) -> Below Goal
A10: Saturday | B10: 1/3/2026 | C10: 0 | D10: 0 | E10: 150 | F10: =IF(D10="","",D10-E10) -> -150 | G10: =IF(F10="","",IF(F10>=0,"Goal Met","Below Goal")) -> Below Goal
A11: Sunday | B11: 1/4/2026 | C11: 0.28 | D11: 31.73 | E11: 150 | F11: =IF(D11="","",D11-E11) -> -118.27 | G11: =IF(F11="","",IF(F11>=0,"Goal Met","Below Goal")) -> Below Goal
A12: Week Total | C12: =DOLLARFR(IFERROR(DOLLARDE(C5,60),0)+IFERROR(DOLLARDE(C6,60),0)+IFERROR(DOLLARDE(C7,60),0)+IFERROR(DOLLARDE(C8,60),0)+IFERROR(DOLLARDE(C9,60),0)+IFERROR(DOLLARDE(C10,60),0)+IFERROR(DOLLARDE(C11,60),0), 60) -> 35.08 | D12: =SUM(D5:D11) -> 978.18 | E12: =SUM(E5:E11) -> 1050 | F12: =D12-E12 -> -71.82 | G12: =IF(D12="","",IF(F12>=0,"Goal Met","Below Goal")) -> Below Goal
A14: Week: Jan 05 - Jan 11
A15: Day | B15: Date | C15: Hours | D15: Daily Earnings | E15: Daily Goal | F15: Difference +/- | G15: Status
A16: Monday | B16: 1/5/2026 | C16: 4 | D16: 85.59 | E16: 150 | F16: =IF(D16="","",D16-E16) -> -64.41 | G16: =IF(F16="","",IF(F16>=0,"Goal Met","Below Goal")) -> Below Goal
A17: Tuesday | B17: 1/6/2026 | C17: 1.58 | D17: 43.94 | E17: 150 | F17: =IF(D17="","",D17-E17) -> -106.06 | G17: =IF(F17="","",IF(F17>=0,"Goal Met","Below Goal")) -> Below Goal
A18: Wednesday | B18: 1/7/2026 | C18: 4.14 | D18: 122.01 | E18: 150 | F18: =IF(D18="","",D18-E18) -> -27.99 | G18: =IF(F18="","",IF(F18>=0,"Goal Met","Below Goal")) -> Below Goal
A19: Thursday | B19: 1/8/2026 | C19: 3.43 | D19: 74.23 | E19: 150 | F19: =IF(D19="","",D19-E19) -> -75.77 | G19: =IF(F19="","",IF(F19>=0,"Goal Met","Below Goal")) -> Below Goal
A20: Friday | B20: 1/9/2026 | C20: 4.36 | D20: 116.26 | E20: 150 | F20: =IF(D20="","",D20-E20) -> -33.74 | G20: =IF(F20="","",IF(F20>=0,"Goal Met","Below Goal")) -> Below Goal
A21: Saturday | B21: 1/10/2026 | C21: 4.56 | D21: 116.84 | E21: 150 | F21: =IF(D21="","",D21-E21) -> -33.16 | G21: =IF(F21="","",IF(F21>=0,"Goal Met","Below Goal")) -> Below Goal
A22: Sunday | B22: 1/11/2026 | C22: 4.59 | D22: 112.09 | E22: 150 | F22: =IF(D22="","",D22-E22) -> -37.91 | G22: =IF(F22="","",IF(F22>=0,"Goal Met","Below Goal")) -> Below Goal
A23: Week Total | C23: =DOLLARFR(IFERROR(DOLLARDE(C16,60),0)+IFERROR(DOLLARDE(C17,60),0)+IFERROR(DOLLARDE(C18,60),0)+IFERROR(DOLLARDE(C19,60),0)+IFERROR(DOLLARDE(C20,60),0)+IFERROR(DOLLARDE(C21,60),0)+IFERROR(DOLLARDE(C22,60),0), 60) -> 28.26 | D23: =SUM(D16:D22) -> 670.96 | E23: =SUM(E16:E22) -> 1050 | F23: =D23-E23 -> -379.04 | G23: =IF(D23="","",IF(F23>=0,"Goal Met","Below Goal")) -> Below Goal
A25: Week: Jan 12 - Jan 18
A26: Day | B26: Date | C26: Hours | D26: Daily Earnings | E26: Daily Goal | F26: Difference +/- | G26: Status
A27: Monday | B27: 1/12/2026 | C27: 3.28 | D27: 66.21 | E27: 150 | F27: =IF(D27="","",D27-E27) -> -83.79 | G27: =IF(F27="","",IF(F27>=0,"Goal Met","Below Goal")) -> Below Goal
A28: Tuesday | B28: 1/13/2026 | C28: 5.12 | D28: 152.29 | E28: 150 | F28: =IF(D28="","",D28-E28) -> 2.29 | G28: =IF(F28="","",IF(F28>=0,"Goal Met","Below Goal")) -> Goal Met
A29: Wednesday | B29: 1/14/2026 | C29: 0 | D29: 0 | E29: 150 | F29: =IF(D29="","",D29-E29) -> -150 | G29: =IF(F29="","",IF(F29>=0,"Goal Met","Below Goal")) -> Below Goal
A30: Thursday | B30: 1/15/2026 | C30: 4.37 | D30: 86.56 | E30: 150 | F30: =IF(D30="","",D30-E30) -> -63.44 | G30: =IF(F30="","",IF(F30>=0,"Goal Met","Below Goal")) -> Below Goal
A31: Friday | B31: 1/16/2026 | C31: 3.57 | D31: 99.01 | E31: 150 | F31: =IF(D31="","",D31-E31) -> -50.99 | G31: =IF(F31="","",IF(F31>=0,"Goal Met","Below Goal")) -> Below Goal
A32: Saturday | B32: 1/17/2026 | C32: 5.49 | D32: 124.7 | E32: 150 | F32: =IF(D32="","",D32-E32) -> -25.3 | G32: =IF(F32="","",IF(F32>=0,"Goal Met","Below Goal")) -> Below Goal
A33: Sunday | B33: 1/18/2026 | C33: 5.41 | D33: 169.34 | E33: 150 | F33: =IF(D33="","",D33-E33) -> 19.34 | G33: =IF(F33="","",IF(F33>=0,"Goal Met","Below Goal")) -> Goal Met
A34: Week Total | C34: =DOLLARFR(IFERROR(DOLLARDE(C27,60),0)+IFERROR(DOLLARDE(C28,60),0)+IFERROR(DOLLARDE(C29,60),0)+IFERROR(DOLLARDE(C30,60),0)+IFERROR(DOLLARDE(C31,60),0)+IFERROR(DOLLARDE(C32,60),0)+IFERROR(DOLLARDE(C33,60),0), 60) -> 28.44 | D34: =SUM(D27:D33) -> 698.11 | E34: =SUM(E27:E33) -> 1050 | F34: =D34-E34 -> -351.89 | G34: =IF(D34="","",IF(F34>=0,"Goal Met","Below Goal")) -> Below Goal
A36: Week: Jan 19 - Jan 25
A37: Day | B37: Date | C37: Hours | D37: Daily Earnings | E37: Daily Goal | F37: Difference +/- | G37: Status
A38: Monday | B38: 1/19/2026 | C38: 5.09 | D38: 124.82 | E38: 150 | F38: =IF(D38="","",D38-E38) -> -25.18 | G38: =IF(F38="","",IF(F38>=0,"Goal Met","Below Goal")) -> Below Goal
A39: Tuesday | B39: 1/20/2026 | C39: 6.12 | D39: 129.02 | E39: 150 | F39: =IF(D39="","",D39-E39) -> -20.98 | G39: =IF(F39="","",IF(F39>=0,"Goal Met","Below Goal")) -> Below Goal
A40: Wednesday | B40: 1/21/2026 | C40: 6.45 | D40: 183.47 | E40: 150 | F40: =IF(D40="","",D40-E40) -> 33.47 | G40: =IF(F40="","",IF(F40>=0,"Goal Met","Below Goal")) -> Goal Met
A41: Thursday | B41: 1/22/2026 | C41: 6.03 | D41: 156.23 | E41: 150 | F41: =IF(D41="","",D41-E41) -> 6.23 | G41: =IF(F41="","",IF(F41>=0,"Goal Met","Below Goal")) -> Goal Met
A42: Friday | B42: 1/23/2026 | C42: 6.34 | D42: 162.85 | E42: 150 | F42: =IF(D42="","",D42-E42) -> 12.85 | G42: =IF(F42="","",IF(F42>=0,"Goal Met","Below Goal")) -> Goal Met
A43: Saturday | B43: 1/24/2026 | C43: 14.24 | D43: 429.4 | E43: 150 | F43: =IF(D43="","",D43-E43) -> 279.4 | G43: =IF(F43="","",IF(F43>=0,"Goal Met","Below Goal")) -> Goal Met
A44: Sunday | B44: 1/25/2026 | C44: 6.47 | D44: 211.95 | E44: 150 | F44: =IF(D44="","",D44-E44) -> 61.95 | G44: =IF(F44="","",IF(F44>=0,"Goal Met","Below Goal")) -> Goal Met
...

Sheet February
A1: TERRANCE MASSEY - February 2026
A3: Week: Feb 02 - Feb 08
A4: Day | B4: Date | C4: Hours | D4: Daily Earnings | E4: Daily Goal | F4: Difference +/- | G4: Status
A5: Monday | B5: 2/2/2026 | D5: 127.22 | E5: 150 | F5: =IF(D5="","",D5-E5) -> -22.78 | G5: =IF(F5="","",IF(F5>=0,"Goal Met","Below Goal")) -> Below Goal
A6: Tuesday | B6: 2/3/2026 | D6: 56.55 | E6: 150 | F6: =IF(D6="","",D6-E6) -> -93.45 | G6: =IF(F6="","",IF(F6>=0,"Goal Met","Below Goal")) -> Below Goal
A7: Wednesday | B7: 2/4/2026 | D7: 0 | E7: 150 | F7: =IF(D7="","",D7-E7) -> -150 | G7: =IF(F7="","",IF(F7>=0,"Goal Met","Below Goal")) -> Below Goal
A8: Thursday | B8: 2/5/2026 | D8: 15.2 | E8: 150 | F8: =IF(D8="","",D8-E8) -> -134.8 | G8: =IF(F8="","",IF(F8>=0,"Goal Met","Below Goal")) -> Below Goal
A9: Friday | B9: 2/6/2026 | D9: 118.49 | E9: 150 | F9: =IF(D9="","",D9-E9) -> -31.51 | G9: =IF(F9="","",IF(F9>=0,"Goal Met","Below Goal")) -> Below Goal
A10: Saturday | B10: 2/7/2026 | D10: 106.36 | E10: 150 | F10: =IF(D10="","",D10-E10) -> -43.64 | G10: =IF(F10="","",IF(F10>=0,"Goal Met","Below Goal")) -> Below Goal
A11: Sunday | B11: 2/8/2026 | D11: 105.49 | E11: 150 | F11: =IF(D11="","",D11-E11) -> -44.51 | G11: =IF(F11="","",IF(F11>=0,"Goal Met","Below Goal")) -> Below Goal
A12: Week Total | C12: =DOLLARFR(IFERROR(DOLLARDE(C5,60),0)+IFERROR(DOLLARDE(C6,60),0)+IFERROR(DOLLARDE(C7,60),0)+IFERROR(DOLLARDE(C8,60),0)+IFERROR(DOLLARDE(C9,60),0)+IFERROR(DOLLARDE(C10,60),0)+IFERROR(DOLLARDE(C11,60),0), 60) -> 0 | D12: =SUM(D5:D11) -> 529.31 | E12: =SUM(E5:E11) -> 1050 | F12: =D12-E12 -> -520.69 | G12: =IF(D12="","",IF(F12>=0,"Goal Met","Below Goal")) -> Below Goal
A14: Week: Feb 09 - Feb 15
A15: Day | B15: Date | C15: Hours | D15: Daily Earnings | E15: Daily Goal | F15: Difference +/- | G15: Status
A16: Monday | B16: 2/9/2026 | C16: 5.49 | D16: 156.52 | E16: 150 | F16: =IF(D16="","",D16-E16) -> 6.52 | G16: =IF(F16="","",IF(F16>=0,"Goal Met","Below Goal")) -> Goal Met
A17: Tuesday | B17: 2/10/2026 | C17: 4.54 | D17: 94.78 | E17: 150 | F17: =IF(D17="","",D17-E17) -> -55.22 | G17: =IF(F17="","",IF(F17>=0,"Goal Met","Below Goal")) -> Below Goal
A18: Wednesday | B18: 2/11/2026 | C18: 4.9 | D18: 119.55 | E18: 150 | F18: =IF(D18="","",D18-E18) -> -30.45 | G18: =IF(F18="","",IF(F18>=0,"Goal Met","Below Goal")) -> Below Goal
A19: Thursday | B19: 2/12/2026 | C19: 3.26 | D19: 99.21 | E19: 150 | F19: =IF(D19="","",D19-E19) -> -50.79 | G19: =IF(F19="","",IF(F19>=0,"Goal Met","Below Goal")) -> Below Goal
A20: Friday | B20: 2/13/2026 | C20: 1.4 | D20: 18.52 | E20: 150 | F20: =IF(D20="","",D20-E20) -> -131.48 | G20: =IF(F20="","",IF(F20>=0,"Goal Met","Below Goal")) -> Below Goal
A21: Saturday | B21: 2/14/2026 | C21: 0 | D21: 0 | E21: 150 | F21: =IF(D21="","",D21-E21) -> -150 | G21: =IF(F21="","",IF(F21>=0,"Goal Met","Below Goal")) -> Below Goal
A22: Sunday | B22: 2/15/2026 | C22: 3.43 | D22: 117.43 | E22: 150 | F22: =IF(D22="","",D22-E22) -> -32.57 | G22: =IF(F22="","",IF(F22>=0,"Goal Met","Below Goal")) -> Below Goal
A23: Week Total | C23: =DOLLARFR(IFERROR(DOLLARDE(C16,60),0)+IFERROR(DOLLARDE(C17,60),0)+IFERROR(DOLLARDE(C18,60),0)+IFERROR(DOLLARDE(C19,60),0)+IFERROR(DOLLARDE(C20,60),0)+IFERROR(DOLLARDE(C21,60),0)+IFERROR(DOLLARDE(C22,60),0), 60) -> 25.02 | D23: =SUM(D16:D22) -> 606.01 | E23: =SUM(E16:E22) -> 1050 | F23: =D23-E23 -> -443.99 | G23: =IF(D23="","",IF(F23>=0,"Goal Met","Below Goal")) -> Below Goal
A25: Week: Feb 16 - Feb 22
A26: Day | B26: Date | C26: Hours | D26: Daily Earnings | E26: Daily Goal | F26: Difference +/- | G26: Status
A27: Monday | B27: 2/16/2026 | C27: 2.59 | D27: 66.38 | E27: 150 | F27: =IF(D27="","",D27-E27) -> -83.62 | G27: =IF(F27="","",IF(F27>=0,"Goal Met","Below Goal")) -> Below Goal
A28: Tuesday | B28: 2/17/2026 | C28: 2.18 | D28: 66.66 | E28: 150 | F28: =IF(D28="","",D28-E28) -> -83.34 | G28: =IF(F28="","",IF(F28>=0,"Goal Met","Below Goal")) -> Below Goal
A29: Wednesday | B29: 2/18/2026 | C29: 0 | D29: 0 | E29: 150 | F29: =IF(D29="","",D29-E29) -> -150 | G29: =IF(F29="","",IF(F29>=0,"Goal Met","Below Goal")) -> Below Goal
A30: Thursday | B30: 2/19/2026 | C30: 0 | D30: 0 | E30: 150 | F30: =IF(D30="","",D30-E30) -> -150 | G30: =IF(F30="","",IF(F30>=0,"Goal Met","Below Goal")) -> Below Goal
A31: Friday | B31: 2/20/2026 | C31: 4.52 | D31: 132.11 | E31: 150 | F31: =IF(D31="","",D31-E31) -> -17.89 | G31: =IF(F31="","",IF(F31>=0,"Goal Met","Below Goal")) -> Below Goal
A32: Saturday | B32: 2/21/2026 | C32: 7.14 | D32: 214.24 | E32: 150 | F32: =IF(D32="","",D32-E32) -> 64.24 | G32: =IF(F32="","",IF(F32>=0,"Goal Met","Below Goal")) -> Goal Met
A33: Sunday | B33: 2/22/2026 | C33: 0 | D33: 0 | E33: 150 | F33: =IF(D33="","",D33-E33) -> -150 | G33: =IF(F33="","",IF(F33>=0,"Goal Met","Below Goal")) -> Below Goal
A34: Week Total | C34: =DOLLARFR(IFERROR(DOLLARDE(C27,60),0)+IFERROR(DOLLARDE(C28,60),0)+IFERROR(DOLLARDE(C29,60),0)+IFERROR(DOLLARDE(C30,60),0)+IFERROR(DOLLARDE(C31,60),0)+IFERROR(DOLLARDE(C32,60),0)+IFERROR(DOLLARDE(C33,60),0), 60) -> 17.23 | D34: =SUM(D27:D33) -> 479.39 | E34: =SUM(E27:E33) -> 1050 | F34: =D34-E34 -> -570.61 | G34: =IF(D34="","",IF(F34>=0,"Goal Met","Below Goal")) -> Below Goal
A36: Week: Feb 23 - Mar 01
A37: Day | B37: Date | C37: Hours | D37: Daily Earnings | E37: Daily Goal | F37: Difference +/- | G37: Status
A38: Monday | B38: 2/23/2026 | C38: 1.1 | D38: 43.22 | E38: 150 | F38: =IF(D38="","",D38-E38) -> -106.78 | G38: =IF(F38="","",IF(F38>=0,"Goal Met","Below Goal")) -> Below Goal
A39: Tuesday | B39: 2/24/2026 | C39: 2.46 | D39: 74.27 | E39: 150 | F39: =IF(D39="","",D39-E39) -> -75.73 | G39: =IF(F39="","",IF(F39>=0,"Goal Met","Below Goal")) -> Below Goal
A40: Wednesday | B40: 2/25/2026 | C40: 1.5 | D40: 49.11 | E40: 150 | F40: =IF(D40="","",D40-E40) -> -100.89 | G40: =IF(F40="","",IF(F40>=0,"Goal Met","Below Goal")) -> Below Goal
A41: Thursday | B41: 2/26/2026 | C41: 1.16 | D41: 57.37 | E41: 150 | F41: =IF(D41="","",D41-E41) -> -92.63 | G41: =IF(F41="","",IF(F41>=0,"Goal Met","Below Goal")) -> Below Goal
A42: Friday | B42: 2/27/2026 | C42: 7.4 | D42: 186.54 | E42: 150 | F42: =IF(D42="","",D42-E42) -> 36.54 | G42: =IF(F42="","",IF(F42>=0,"Goal Met","Below Goal")) -> Goal Met
A43: Saturday | B43: 2/28/2026 | C43: 7.36 | D43: 250.38 | E43: 150 | F43: =IF(D43="","",D43-E43) -> 100.38 | G43: =IF(F43="","",IF(F43>=0,"Goal Met","Below Goal")) -> Goal Met
A44: Sunday | B44: 3/1/2026 | C44: 6.1 | D44: 179.27 | E44: 150 | F44: =IF(D44="","",D44-E44) -> 29.27 | G44: =IF(F44="","",IF(F44>=0,"Goal Met","Below Goal")) -> Goal Met
...

Sheet March
A1: TERRANCE MASSEY - March 2026
A3: Week: Mar 02 - Mar 08
A4: Day | B4: Date | C4: Hours | D4: Daily Earnings | E4: Daily Goal | F4: Difference +/- | G4: Status
A5: Monday | B5: 3/2/2026 | C5: 8.53 | D5: 224.7 | E5: 150 | F5: =IF(D5="","",D5-E5) -> 74.7 | G5: =IF(F5="","",IF(F5>=0,"Goal Met","Below Goal")) -> Goal Met
A6: Tuesday | B6: 3/3/2026 | E6: 150 | F6: =IF(D6="","",D6-E6) | G6: =IF(F6="","",IF(F6>=0,"Goal Met","Below Goal"))
A7: Wednesday | B7: 3/4/2026 | E7: 150 | F7: =IF(D7="","",D7-E7) | G7: =IF(F7="","",IF(F7>=0,"Goal Met","Below Goal"))
A8: Thursday | B8: 3/5/2026 | E8: 150 | F8: =IF(D8="","",D8-E8) | G8: =IF(F8="","",IF(F8>=0,"Goal Met","Below Goal"))
A9: Friday | B9: 3/6/2026 | E9: 150 | F9: =IF(D9="","",D9-E9) | G9: =IF(F9="","",IF(F9>=0,"Goal Met","Below Goal"))
A10: Saturday | B10: 3/7/2026 | E10: 150 | F10: =IF(D10="","",D10-E10) | G10: =IF(F10="","",IF(F10>=0,"Goal Met","Below Goal"))
A11: Sunday | B11: 3/8/2026 | E11: 150 | F11: =IF(D11="","",D11-E11) | G11: =IF(F11="","",IF(F11>=0,"Goal Met","Below Goal"))
A12: Week Total | C12: =DOLLARFR(IFERROR(DOLLARDE(C5,60),0)+IFERROR(DOLLARDE(C6,60),0)+IFERROR(DOLLARDE(C7,60),0)+IFERROR(DOLLARDE(C8,60),0)+IFERROR(DOLLARDE(C9,60),0)+IFERROR(DOLLARDE(C10,60),0)+IFERROR(DOLLARDE(C11,60),0), 60) -> 8.53 | D12: =SUM(D5:D11) -> 224.7 | E12: =SUM(E5:E11) -> 1050 | F12: =D12-E12 -> -825.3 | G12: =IF(D12="","",IF(F12>=0,"Goal Met","Below Goal")) -> Below Goal
A14: Week: Mar 09 - Mar 15
A15: Day | B15: Date | C15: Hours | D15: Daily Earnings | E15: Daily Goal | F15: Difference +/- | G15: Status
A16: Monday | B16: 3/9/2026 | E16: 150 | F16: =IF(D16="","",D16-E16) | G16: =IF(F16="","",IF(F16>=0,"Goal Met","Below Goal"))
A17: Tuesday | B17: 3/10/2026 | E17: 150 | F17: =IF(D17="","",D17-E17) | G17: =IF(F17="","",IF(F17>=0,"Goal Met","Below Goal"))
A18: Wednesday | B18: 3/11/2026 | E18: 150 | F18: =IF(D18="","",D18-E18) | G18: =IF(F18="","",IF(F18>=0,"Goal Met","Below Goal"))
A19: Thursday | B19: 3/12/2026 | E19: 150 | F19: =IF(D19="","",D19-E19) | G19: =IF(F19="","",IF(F19>=0,"Goal Met","Below Goal"))
A20: Friday | B20: 3/13/2026 | E20: 150 | F20: =IF(D20="","",D20-E20) | G20: =IF(F20="","",IF(F20>=0,"Goal Met","Below Goal"))
A21: Saturday | B21: 3/14/2026 | E21: 150 | F21: =IF(D21="","",D21-E21) | G21: =IF(F21="","",IF(F21>=0,"Goal Met","Below Goal"))
A22: Sunday | B22: 3/15/2026 | E22: 150 | F22: =IF(D22="","",D22-E22) | G22: =IF(F22="","",IF(F22>=0,"Goal Met","Below Goal"))
A23: Week Total | C23: =DOLLARFR(IFERROR(DOLLARDE(C16,60),0)+IFERROR(DOLLARDE(C17,60),0)+IFERROR(DOLLARDE(C18,60),0)+IFERROR(DOLLARDE(C19,60),0)+IFERROR(DOLLARDE(C20,60),0)+IFERROR(DOLLARDE(C21,60),0)+IFERROR(DOLLARDE(C22,60),0), 60) -> 0 | D23: =SUM(D16:D22) -> 0 | E23: =SUM(E16:E22) -> 1050 | F23: =D23-E23 -> -1050 | G23: =IF(D23="","",IF(F23>=0,"Goal Met","Below Goal")) -> Below Goal
A25: Week: Mar 16 - Mar 22
A26: Day | B26: Date | C26: Hours | D26: Daily Earnings | E26: Daily Goal | F26: Difference +/- | G26: Status
A27: Monday | B27: 3/16/2026 | E27: 150 | F27: =IF(D27="","",D27-E27) | G27: =IF(F27="","",IF(F27>=0,"Goal Met","Below Goal"))
A28: Tuesday | B28: 3/17/2026 | E28: 150 | F28: =IF(D28="","",D28-E28) | G28: =IF(F28="","",IF(F28>=0,"Goal Met","Below Goal"))
A29: Wednesday | B29: 3/18/2026 | E29: 150 | F29: =IF(D29="","",D29-E29) | G29: =IF(F29="","",IF(F29>=0,"Goal Met","Below Goal"))
A30: Thursday | B30: 3/19/2026 | E30: 150 | F30: =IF(D30="","",D30-E30) | G30: =IF(F30="","",IF(F30>=0,"Goal Met","Below Goal"))
A31: Friday | B31: 3/20/2026 | E31: 150 | F31: =IF(D31="","",D31-E31) | G31: =IF(F31="","",IF(F31>=0,"Goal Met","Below Goal"))
A32: Saturday | B32: 3/21/2026 | E32: 150 | F32: =IF(D32="","",D32-E32) | G32: =IF(F32="","",IF(F32>=0,"Goal Met","Below Goal"))
A33: Sunday | B33: 3/22/2026 | E33: 150 | F33: =IF(D33="","",D33-E33) | G33: =IF(F33="","",IF(F33>=0,"Goal Met","Below Goal"))
A34: Week Total | C34: =DOLLARFR(IFERROR(DOLLARDE(C27,60),0)+IFERROR(DOLLARDE(C28,60),0)+IFERROR(DOLLARDE(C29,60),0)+IFERROR(DOLLARDE(C30,60),0)+IFERROR(DOLLARDE(C31,60),0)+IFERROR(DOLLARDE(C32,60),0)+IFERROR(DOLLARDE(C33,60),0), 60) -> 0 | D34: =SUM(D27:D33) -> 0 | E34: =SUM(E27:E33) -> 1050 | F34: =D34-E34 -> -1050 | G34: =IF(D34="","",IF(F34>=0,"Goal Met","Below Goal")) -> Below Goal
A36: Week: Mar 23 - Mar 29
A37: Day | B37: Date | C37: Hours | D37: Daily Earnings | E37: Daily Goal | F37: Difference +/- | G37: Status
A38: Monday | B38: 3/23/2026 | E38: 150 | F38: =IF(D38="","",D38-E38) | G38: =IF(F38="","",IF(F38>=0,"Goal Met","Below Goal"))
A39: Tuesday | B39: 3/24/2026 | E39: 150 | F39: =IF(D39="","",D39-E39) | G39: =IF(F39="","",IF(F39>=0,"Goal Met","Below Goal"))
A40: Wednesday | B40: 3/25/2026 | E40: 150 | F40: =IF(D40="","",D40-E40) | G40: =IF(F40="","",IF(F40>=0,"Goal Met","Below Goal"))
A41: Thursday | B41: 3/26/2026 | E41: 150 | F41: =IF(D41="","",D41-E41) | G41: =IF(F41="","",IF(F41>=0,"Goal Met","Below Goal"))
A42: Friday | B42: 3/27/2026 | E42: 150 | F42: =IF(D42="","",D42-E42) | G42: =IF(F42="","",IF(F42>=0,"Goal Met","Below Goal"))
A43: Saturday | B43: 3/28/2026 | E43: 150 | F43: =IF(D43="","",D43-E43) | G43: =IF(F43="","",IF(F43>=0,"Goal Met","Below Goal"))
A44: Sunday | B44: 3/29/2026 | E44: 150 | F44: =IF(D44="","",D44-E44) | G44: =IF(F44="","",IF(F44>=0,"Goal Met","Below Goal"))
...

Sheet April
A1: TERRANCE MASSEY - April 2026
A3: Week: Mar 30 - Apr 05
A4: Day | B4: Date | C4: Hours | D4: Daily Earnings | E4: Daily Goal | F4: Difference +/- | G4: Status
A5: Monday | B5: 3/30/2026 | E5: 175 | F5: =IF(D5="","",D5-E5) | G5: =IF(F5="","",IF(F5>=0,"Goal Met","Below Goal"))
A6: Tuesday | B6: 3/31/2026 | E6: 175 | F6: =IF(D6="","",D6-E6) | G6: =IF(F6="","",IF(F6>=0,"Goal Met","Below Goal"))
A7: Wednesday | B7: 4/1/2026 | E7: 175 | F7: =IF(D7="","",D7-E7) | G7: =IF(F7="","",IF(F7>=0,"Goal Met","Below Goal"))
A8: Thursday | B8: 4/2/2026 | E8: 175 | F8: =IF(D8="","",D8-E8) | G8: =IF(F8="","",IF(F8>=0,"Goal Met","Below Goal"))
A9: Friday | B9: 4/3/2026 | E9: 175 | F9: =IF(D9="","",D9-E9) | G9: =IF(F9="","",IF(F9>=0,"Goal Met","Below Goal"))
A10: Saturday | B10: 4/4/2026 | E10: 175 | F10: =IF(D10="","",D10-E10) | G10: =IF(F10="","",IF(F10>=0,"Goal Met","Below Goal"))
A11: Sunday | B11: 4/5/2026 | E11: 175 | F11: =IF(D11="","",D11-E11) | G11: =IF(F11="","",IF(F11>=0,"Goal Met","Below Goal"))
A12: Week Total | C12: =DOLLARFR(IFERROR(DOLLARDE(C5,60),0)+IFERROR(DOLLARDE(C6,60),0)+IFERROR(DOLLARDE(C7,60),0)+IFERROR(DOLLARDE(C8,60),0)+IFERROR(DOLLARDE(C9,60),0)+IFERROR(DOLLARDE(C10,60),0)+IFERROR(DOLLARDE(C11,60),0), 60) -> 0 | D12: =SUM(D5:D11) -> 0 | E12: =SUM(E5:E11) -> 1225 | F12: =D12-E12 -> -1225 | G12: =IF(D12="","",IF(F12>=0,"Goal Met","Below Goal")) -> Below Goal
A14: Week: Apr 06 - Apr 12
A15: Day | B15: Date | C15: Hours | D15: Daily Earnings | E15: Daily Goal | F15: Difference +/- | G15: Status
A16: Monday | B16: 4/6/2026 | E16: 175 | F16: =IF(D16="","",D16-E16) | G16: =IF(F16="","",IF(F16>=0,"Goal Met","Below Goal"))
A17: Tuesday | B17: 4/7/2026 | E17: 175 | F17: =IF(D17="","",D17-E17) | G17: =IF(F17="","",IF(F17>=0,"Goal Met","Below Goal"))
A18: Wednesday | B18: 4/8/2026 | E18: 175 | F18: =IF(D18="","",D18-E18) | G18: =IF(F18="","",IF(F18>=0,"Goal Met","Below Goal"))
A19: Thursday | B19: 4/9/2026 | E19: 175 | F19: =IF(D19="","",D19-E19) | G19: =IF(F19="","",IF(F19>=0,"Goal Met","Below Goal"))
A20: Friday | B20: 4/10/2026 | E20: 175 | F20: =IF(D20="","",D20-E20) | G20: =IF(F20="","",IF(F20>=0,"Goal Met","Below Goal"))
A21: Saturday | B21: 4/11/2026 | E21: 175 | F21: =IF(D21="","",D21-E21) | G21: =IF(F21="","",IF(F21>=0,"Goal Met","Below Goal"))
A22: Sunday | B22: 4/12/2026 | E22: 175 | F22: =IF(D22="","",D22-E22) | G22: =IF(F22="","",IF(F22>=0,"Goal Met","Below Goal"))
A23: Week Total | C23: =DOLLARFR(IFERROR(DOLLARDE(C16,60),0)+IFERROR(DOLLARDE(C17,60),0)+IFERROR(DOLLARDE(C18,60),0)+IFERROR(DOLLARDE(C19,60),0)+IFERROR(DOLLARDE(C20,60),0)+IFERROR(DOLLARDE(C21,60),0)+IFERROR(DOLLARDE(C22,60),0), 60) -> 0 | D23: =SUM(D16:D22) -> 0 | E23: =SUM(E16:E22) -> 1225 | F23: =D23-E23 -> -1225 | G23: =IF(D23="","",IF(F23>=0,"Goal Met","Below Goal")) -> Below Goal
A25: Week: Apr 13 - Apr 19
A26: Day | B26: Date | C26: Hours | D26: Daily Earnings | E26: Daily Goal | F26: Difference +/- | G26: Status
A27: Monday | B27: 4/13/2026 | E27: 175 | F27: =IF(D27="","",D27-E27) | G27: =IF(F27="","",IF(F27>=0,"Goal Met","Below Goal"))
A28: Tuesday | B28: 4/14/2026 | E28: 175 | F28: =IF(D28="","",D28-E28) | G28: =IF(F28="","",IF(F28>=0,"Goal Met","Below Goal"))
A29: Wednesday | B29: 4/15/2026 | E29: 175 | F29: =IF(D29="","",D29-E29) | G29: =IF(F29="","",IF(F29>=0,"Goal Met","Below Goal"))
A30: Thursday | B30: 4/16/2026 | E30: 175 | F30: =IF(D30="","",D30-E30) | G30: =IF(F30="","",IF(F30>=0,"Goal Met","Below Goal"))
A31: Friday | B31: 4/17/2026 | E31: 175 | F31: =IF(D31="","",D31-E31) | G31: =IF(F31="","",IF(F31>=0,"Goal Met","Below Goal"))
A32: Saturday | B32: 4/18/2026 | E32: 175 | F32: =IF(D32="","",D32-E32) | G32: =IF(F32="","",IF(F32>=0,"Goal Met","Below Goal"))
A33: Sunday | B33: 4/19/2026 | E33: 175 | F33: =IF(D33="","",D33-E33) | G33: =IF(F33="","",IF(F33>=0,"Goal Met","Below Goal"))
A34: Week Total | C34: =DOLLARFR(IFERROR(DOLLARDE(C27,60),0)+IFERROR(DOLLARDE(C28,60),0)+IFERROR(DOLLARDE(C29,60),0)+IFERROR(DOLLARDE(C30,60),0)+IFERROR(DOLLARDE(C31,60),0)+IFERROR(DOLLARDE(C32,60),0)+IFERROR(DOLLARDE(C33,60),0), 60) -> 0 | D34: =SUM(D27:D33) -> 0 | E34: =SUM(E27:E33) -> 1225 | F34: =D34-E34 -> -1225 | G34: =IF(D34="","",IF(F34>=0,"Goal Met","Below Goal")) -> Below Goal
A36: Week: Apr 20 - Apr 26
A37: Day | B37: Date | C37: Hours | D37: Daily Earnings | E37: Daily Goal | F37: Difference +/- | G37: Status
A38: Monday | B38: 4/20/2026 | E38: 175 | F38: =IF(D38="","",D38-E38) | G38: =IF(F38="","",IF(F38>=0,"Goal Met","Below Goal"))
A39: Tuesday | B39: 4/21/2026 | E39: 175 | F39: =IF(D39="","",D39-E39) | G39: =IF(F39="","",IF(F39>=0,"Goal Met","Below Goal"))
A40: Wednesday | B40: 4/22/2026 | E40: 175 | F40: =IF(D40="","",D40-E40) | G40: =IF(F40="","",IF(F40>=0,"Goal Met","Below Goal"))
A41: Thursday | B41: 4/23/2026 | E41: 175 | F41: =IF(D41="","",D41-E41) | G41: =IF(F41="","",IF(F41>=0,"Goal Met","Below Goal"))
A42: Friday | B42: 4/24/2026 | E42: 175 | F42: =IF(D42="","",D42-E42) | G42: =IF(F42="","",IF(F42>=0,"Goal Met","Below Goal"))
A43: Saturday | B43: 4/25/2026 | E43: 175 | F43: =IF(D43="","",D43-E43) | G43: =IF(F43="","",IF(F43>=0,"Goal Met","Below Goal"))
A44: Sunday | B44: 4/26/2026 | E44: 175 | F44: =IF(D44="","",D44-E44) | G44: =IF(F44="","",IF(F44>=0,"Goal Met","Below Goal"))
...

Sheet May
A1: TERRANCE MASSEY - May 2026
A3: Week: May 04 - May 10
A4: Day | B4: Date | C4: Hours | D4: Daily Earnings | E4: Daily Goal | F4: Difference +/- | G4: Status
A5: Monday | B5: 5/4/2026 | E5: 175 | F5: =IF(D5="","",D5-E5) | G5: =IF(F5="","",IF(F5>=0,"Goal Met","Below Goal"))
A6: Tuesday | B6: 5/5/2026 | E6: 175 | F6: =IF(D6="","",D6-E6) | G6: =IF(F6="","",IF(F6>=0,"Goal Met","Below Goal"))
A7: Wednesday | B7: 5/6/2026 | E7: 175 | F7: =IF(D7="","",D7-E7) | G7: =IF(F7="","",IF(F7>=0,"Goal Met","Below Goal"))
A8: Thursday | B8: 5/7/2026 | E8: 175 | F8: =IF(D8="","",D8-E8) | G8: =IF(F8="","",IF(F8>=0,"Goal Met","Below Goal"))
A9: Friday | B9: 5/8/2026 | E9: 175 | F9: =IF(D9="","",D9-E9) | G9: =IF(F9="","",IF(F9>=0,"Goal Met","Below Goal"))
A10: Saturday | B10: 5/9/2026 | E10: 175 | F10: =IF(D10="","",D10-E10) | G10: =IF(F10="","",IF(F10>=0,"Goal Met","Below Goal"))
A11: Sunday | B11: 5/10/2026 | E11: 175 | F11: =IF(D11="","",D11-E11) | G11: =IF(F11="","",IF(F11>=0,"Goal Met","Below Goal"))
A12: Week Total | C12: =DOLLARFR(IFERROR(DOLLARDE(C5,60),0)+IFERROR(DOLLARDE(C6,60),0)+IFERROR(DOLLARDE(C7,60),0)+IFERROR(DOLLARDE(C8,60),0)+IFERROR(DOLLARDE(C9,60),0)+IFERROR(DOLLARDE(C10,60),0)+IFERROR(DOLLARDE(C11,60),0), 60) -> 0 | D12: =SUM(D5:D11) -> 0 | E12: =SUM(E5:E11) -> 1225 | F12: =D12-E12 -> -1225 | G12: =IF(D12="","",IF(F12>=0,"Goal Met","Below Goal")) -> Below Goal
A14: Week: May 11 - May 17
A15: Day | B15: Date | C15: Hours | D15: Daily Earnings | E15: Daily Goal | F15: Difference +/- | G15: Status
A16: Monday | B16: 5/11/2026 | E16: 175 | F16: =IF(D16="","",D16-E16) | G16: =IF(F16="","",IF(F16>=0,"Goal Met","Below Goal"))
A17: Tuesday | B17: 5/12/2026 | E17: 175 | F17: =IF(D17="","",D17-E17) | G17: =IF(F17="","",IF(F17>=0,"Goal Met","Below Goal"))
A18: Wednesday | B18: 5/13/2026 | E18: 175 | F18: =IF(D18="","",D18-E18) | G18: =IF(F18="","",IF(F18>=0,"Goal Met","Below Goal"))
A19: Thursday | B19: 5/14/2026 | E19: 175 | F19: =IF(D19="","",D19-E19) | G19: =IF(F19="","",IF(F19>=0,"Goal Met","Below Goal"))
A20: Friday | B20: 5/15/2026 | E20: 175 | F20: =IF(D20="","",D20-E20) | G20: =IF(F20="","",IF(F20>=0,"Goal Met","Below Goal"))
A21: Saturday | B21: 5/16/2026 | E21: 175 | F21: =IF(D21="","",D21-E21) | G21: =IF(F21="","",IF(F21>=0,"Goal Met","Below Goal"))
A22: Sunday | B22: 5/17/2026 | E22: 175 | F22: =IF(D22="","",D22-E22) | G22: =IF(F22="","",IF(F22>=0,"Goal Met","Below Goal"))
A23: Week Total | C23: =DOLLARFR(IFERROR(DOLLARDE(C16,60),0)+IFERROR(DOLLARDE(C17,60),0)+IFERROR(DOLLARDE(C18,60),0)+IFERROR(DOLLARDE(C19,60),0)+IFERROR(DOLLARDE(C20,60),0)+IFERROR(DOLLARDE(C21,60),0)+IFERROR(DOLLARDE(C22,60),0), 60) -> 0 | D23: =SUM(D16:D22) -> 0 | E23: =SUM(E16:E22) -> 1225 | F23: =D23-E23 -> -1225 | G23: =IF(D23="","",IF(F23>=0,"Goal Met","Below Goal")) -> Below Goal
A25: Week: May 18 - May 24
A26: Day | B26: Date | C26: Hours | D26: Daily Earnings | E26: Daily Goal | F26: Difference +/- | G26: Status
A27: Monday | B27: 5/18/2026 | E27: 175 | F27: =IF(D27="","",D27-E27) | G27: =IF(F27="","",IF(F27>=0,"Goal Met","Below Goal"))
A28: Tuesday | B28: 5/19/2026 | E28: 175 | F28: =IF(D28="","",D28-E28) | G28: =IF(F28="","",IF(F28>=0,"Goal Met","Below Goal"))
A29: Wednesday | B29: 5/20/2026 | E29: 175 | F29: =IF(D29="","",D29-E29) | G29: =IF(F29="","",IF(F29>=0,"Goal Met","Below Goal"))
A30: Thursday | B30: 5/21/2026 | E30: 175 | F30: =IF(D30="","",D30-E30) | G30: =IF(F30="","",IF(F30>=0,"Goal Met","Below Goal"))
A31: Friday | B31: 5/22/2026 | E31: 175 | F31: =IF(D31="","",D31-E31) | G31: =IF(F31="","",IF(F31>=0,"Goal Met","Below Goal"))
A32: Saturday | B32: 5/23/2026 | E32: 175 | F32: =IF(D32="","",D32-E32) | G32: =IF(F32="","",IF(F32>=0,"Goal Met","Below Goal"))
A33: Sunday | B33: 5/24/2026 | E33: 175 | F33: =IF(D33="","",D33-E33) | G33: =IF(F33="","",IF(F33>=0,"Goal Met","Below Goal"))
A34: Week Total | C34: =DOLLARFR(IFERROR(DOLLARDE(C27,60),0)+IFERROR(DOLLARDE(C28,60),0)+IFERROR(DOLLARDE(C29,60),0)+IFERROR(DOLLARDE(C30,60),0)+IFERROR(DOLLARDE(C31,60),0)+IFERROR(DOLLARDE(C32,60),0)+IFERROR(DOLLARDE(C33,60),0), 60) -> 0 | D34: =SUM(D27:D33) -> 0 | E34: =SUM(E27:E33) -> 1225 | F34: =D34-E34 -> -1225 | G34: =IF(D34="","",IF(F34>=0,"Goal Met","Below Goal")) -> Below Goal
A36: Week: May 25 - May 31
A37: Day | B37: Date | C37: Hours | D37: Daily Earnings | E37: Daily Goal | F37: Difference +/- | G37: Status
A38: Monday | B38: 5/25/2026 | E38: 175 | F38: =IF(D38="","",D38-E38) | G38: =IF(F38="","",IF(F38>=0,"Goal Met","Below Goal"))
A39: Tuesday | B39: 5/26/2026 | E39: 175 | F39: =IF(D39="","",D39-E39) | G39: =IF(F39="","",IF(F39>=0,"Goal Met","Below Goal"))
A40: Wednesday | B40: 5/27/2026 | E40: 175 | F40: =IF(D40="","",D40-E40) | G40: =IF(F40="","",IF(F40>=0,"Goal Met","Below Goal"))
A41: Thursday | B41: 5/28/2026 | E41: 175 | F41: =IF(D41="","",D41-E41) | G41: =IF(F41="","",IF(F41>=0,"Goal Met","Below Goal"))
A42: Friday | B42: 5/29/2026 | E42: 175 | F42: =IF(D42="","",D42-E42) | G42: =IF(F42="","",IF(F42>=0,"Goal Met","Below Goal"))
A43: Saturday | B43: 5/30/2026 | E43: 175 | F43: =IF(D43="","",D43-E43) | G43: =IF(F43="","",IF(F43>=0,"Goal Met","Below Goal"))
A44: Sunday | B44: 5/31/2026 | E44: 175 | F44: =IF(D44="","",D44-E44) | G44: =IF(F44="","",IF(F44>=0,"Goal Met","Below Goal"))
...

Sheet June
A1: TERRANCE MASSEY - June 2026
A3: Week: Jun 01 - Jun 07
A4: Day | B4: Date | C4: Hours | D4: Daily Earnings | E4: Daily Goal | F4: Difference +/- | G4: Status
A5: Monday | B5: 6/1/2026 | E5: 175 | F5: =IF(D5="","",D5-E5) | G5: =IF(F5="","",IF(F5>=0,"Goal Met","Below Goal"))
A6: Tuesday | B6: 6/2/2026 | E6: 175 | F6: =IF(D6="","",D6-E6) | G6: =IF(F6="","",IF(F6>=0,"Goal Met","Below Goal"))
A7: Wednesday | B7: 6/3/2026 | E7: 175 | F7: =IF(D7="","",D7-E7) | G7: =IF(F7="","",IF(F7>=0,"Goal Met","Below Goal"))
A8: Thursday | B8: 6/4/2026 | E8: 175 | F8: =IF(D8="","",D8-E8) | G8: =IF(F8="","",IF(F8>=0,"Goal Met","Below Goal"))
A9: Friday | B9: 6/5/2026 | E9: 175 | F9: =IF(D9="","",D9-E9) | G9: =IF(F9="","",IF(F9>=0,"Goal Met","Below Goal"))
A10: Saturday | B10: 6/6/2026 | E10: 175 | F10: =IF(D10="","",D10-E10) | G10: =IF(F10="","",IF(F10>=0,"Goal Met","Below Goal"))
A11: Sunday | B11: 6/7/2026 | E11: 175 | F11: =IF(D11="","",D11-E11) | G11: =IF(F11="","",IF(F11>=0,"Goal Met","Below Goal"))
A12: Week Total | C12: =DOLLARFR(IFERROR(DOLLARDE(C5,60),0)+IFERROR(DOLLARDE(C6,60),0)+IFERROR(DOLLARDE(C7,60),0)+IFERROR(DOLLARDE(C8,60),0)+IFERROR(DOLLARDE(C9,60),0)+IFERROR(DOLLARDE(C10,60),0)+IFERROR(DOLLARDE(C11,60),0), 60) -> 0 | D12: =SUM(D5:D11) -> 0 | E12: =SUM(E5:E11) -> 1225 | F12: =D12-E12 -> -1225 | G12: =IF(D12="","",IF(F12>=0,"Goal Met","Below Goal")) -> Below Goal
A14: Week: Jun 08 - Jun 14
A15: Day | B15: Date | C15: Hours | D15: Daily Earnings | E15: Daily Goal | F15: Difference +/- | G15: Status
A16: Monday | B16: 6/8/2026 | E16: 175 | F16: =IF(D16="","",D16-E16) | G16: =IF(F16="","",IF(F16>=0,"Goal Met","Below Goal"))
A17: Tuesday | B17: 6/9/2026 | E17: 175 | F17: =IF(D17="","",D17-E17) | G17: =IF(F17="","",IF(F17>=0,"Goal Met","Below Goal"))
A18: Wednesday | B18: 6/10/2026 | E18: 175 | F18: =IF(D18="","",D18-E18) | G18: =IF(F18="","",IF(F18>=0,"Goal Met","Below Goal"))
A19: Thursday | B19: 6/11/2026 | E19: 175 | F19: =IF(D19="","",D19-E19) | G19: =IF(F19="","",IF(F19>=0,"Goal Met","Below Goal"))
A20: Friday | B20: 6/12/2026 | E20: 175 | F20: =IF(D20="","",D20-E20) | G20: =IF(F20="","",IF(F20>=0,"Goal Met","Below Goal"))
A21: Saturday | B21: 6/13/2026 | E21: 175 | F21: =IF(D21="","",D21-E21) | G21: =IF(F21="","",IF(F21>=0,"Goal Met","Below Goal"))
A22: Sunday | B22: 6/14/2026 | E22: 175 | F22: =IF(D22="","",D22-E22) | G22: =IF(F22="","",IF(F22>=0,"Goal Met","Below Goal"))
A23: Week Total | C23: =DOLLARFR(IFERROR(DOLLARDE(C16,60),0)+IFERROR(DOLLARDE(C17,60),0)+IFERROR(DOLLARDE(C18,60),0)+IFERROR(DOLLARDE(C19,60),0)+IFERROR(DOLLARDE(C20,60),0)+IFERROR(DOLLARDE(C21,60),0)+IFERROR(DOLLARDE(C22,60),0), 60) -> 0 | D23: =SUM(D16:D22) -> 0 | E23: =SUM(E16:E22) -> 1225 | F23: =D23-E23 -> -1225 | G23: =IF(D23="","",IF(F23>=0,"Goal Met","Below Goal")) -> Below Goal
A25: Week: Jun 15 - Jun 21
A26: Day | B26: Date | C26: Hours | D26: Daily Earnings | E26: Daily Goal | F26: Difference +/- | G26: Status
A27: Monday | B27: 6/15/2026 | E27: 175 | F27: =IF(D27="","",D27-E27) | G27: =IF(F27="","",IF(F27>=0,"Goal Met","Below Goal"))
A28: Tuesday | B28: 6/16/2026 | E28: 175 | F28: =IF(D28="","",D28-E28) | G28: =IF(F28="","",IF(F28>=0,"Goal Met","Below Goal"))
A29: Wednesday | B29: 6/17/2026 | E29: 175 | F29: =IF(D29="","",D29-E29) | G29: =IF(F29="","",IF(F29>=0,"Goal Met","Below Goal"))
A30: Thursday | B30: 6/18/2026 | E30: 175 | F30: =IF(D30="","",D30-E30) | G30: =IF(F30="","",IF(F30>=0,"Goal Met","Below Goal"))
A31: Friday | B31: 6/19/2026 | E31: 175 | F31: =IF(D31="","",D31-E31) | G31: =IF(F31="","",IF(F31>=0,"Goal Met","Below Goal"))
A32: Saturday | B32: 6/20/2026 | E32: 175 | F32: =IF(D32="","",D32-E32) | G32: =IF(F32="","",IF(F32>=0,"Goal Met","Below Goal"))
A33: Sunday | B33: 6/21/2026 | E33: 175 | F33: =IF(D33="","",D33-E33) | G33: =IF(F33="","",IF(F33>=0,"Goal Met","Below Goal"))
A34: Week Total | C34: =DOLLARFR(IFERROR(DOLLARDE(C27,60),0)+IFERROR(DOLLARDE(C28,60),0)+IFERROR(DOLLARDE(C29,60),0)+IFERROR(DOLLARDE(C30,60),0)+IFERROR(DOLLARDE(C31,60),0)+IFERROR(DOLLARDE(C32,60),0)+IFERROR(DOLLARDE(C33,60),0), 60) -> 0 | D34: =SUM(D27:D33) -> 0 | E34: =SUM(E27:E33) -> 1225 | F34: =D34-E34 -> -1225 | G34: =IF(D34="","",IF(F34>=0,"Goal Met","Below Goal")) -> Below Goal
A36: Week: Jun 22 - Jun 28
A37: Day | B37: Date | C37: Hours | D37: Daily Earnings | E37: Daily Goal | F37: Difference +/- | G37: Status
A38: Monday | B38: 6/22/2026 | E38: 175 | F38: =IF(D38="","",D38-E38) | G38: =IF(F38="","",IF(F38>=0,"Goal Met","Below Goal"))
A39: Tuesday | B39: 6/23/2026 | E39: 175 | F39: =IF(D39="","",D39-E39) | G39: =IF(F39="","",IF(F39>=0,"Goal Met","Below Goal"))
A40: Wednesday | B40: 6/24/2026 | E40: 175 | F40: =IF(D40="","",D40-E40) | G40: =IF(F40="","",IF(F40>=0,"Goal Met","Below Goal"))
A41: Thursday | B41: 6/25/2026 | E41: 175 | F41: =IF(D41="","",D41-E41) | G41: =IF(F41="","",IF(F41>=0,"Goal Met","Below Goal"))
A42: Friday | B42: 6/26/2026 | E42: 175 | F42: =IF(D42="","",D42-E42) | G42: =IF(F42="","",IF(F42>=0,"Goal Met","Below Goal"))
A43: Saturday | B43: 6/27/2026 | E43: 175 | F43: =IF(D43="","",D43-E43) | G43: =IF(F43="","",IF(F43>=0,"Goal Met","Below Goal"))
A44: Sunday | B44: 6/28/2026 | E44: 175 | F44: =IF(D44="","",D44-E44) | G44: =IF(F44="","",IF(F44>=0,"Goal Met","Below Goal"))
...

Sheet July
A1: TERRANCE MASSEY - July 2026
A3: Week: Jun 29 - Jul 05
A4: Day | B4: Date | C4: Hours | D4: Daily Earnings | E4: Daily Goal | F4: Difference +/- | G4: Status
A5: Monday | B5: 6/29/2026 | E5: 175 | F5: =IF(D5="","",D5-E5) | G5: =IF(F5="","",IF(F5>=0,"Goal Met","Below Goal"))
A6: Tuesday | B6: 6/30/2026 | E6: 175 | F6: =IF(D6="","",D6-E6) | G6: =IF(F6="","",IF(F6>=0,"Goal Met","Below Goal"))
A7: Wednesday | B7: 7/1/2026 | E7: 175 | F7: =IF(D7="","",D7-E7) | G7: =IF(F7="","",IF(F7>=0,"Goal Met","Below Goal"))
A8: Thursday | B8: 7/2/2026 | E8: 175 | F8: =IF(D8="","",D8-E8) | G8: =IF(F8="","",IF(F8>=0,"Goal Met","Below Goal"))
A9: Friday | B9: 7/3/2026 | E9: 175 | F9: =IF(D9="","",D9-E9) | G9: =IF(F9="","",IF(F9>=0,"Goal Met","Below Goal"))
A10: Saturday | B10: 7/4/2026 | E10: 175 | F10: =IF(D10="","",D10-E10) | G10: =IF(F10="","",IF(F10>=0,"Goal Met","Below Goal"))
A11: Sunday | B11: 7/5/2026 | E11: 175 | F11: =IF(D11="","",D11-E11) | G11: =IF(F11="","",IF(F11>=0,"Goal Met","Below Goal"))
A12: Week Total | C12: =DOLLARFR(IFERROR(DOLLARDE(C5,60),0)+IFERROR(DOLLARDE(C6,60),0)+IFERROR(DOLLARDE(C7,60),0)+IFERROR(DOLLARDE(C8,60),0)+IFERROR(DOLLARDE(C9,60),0)+IFERROR(DOLLARDE(C10,60),0)+IFERROR(DOLLARDE(C11,60),0), 60) -> 0 | D12: =SUM(D5:D11) -> 0 | E12: =SUM(E5:E11) -> 1225 | F12: =D12-E12 -> -1225 | G12: =IF(D12="","",IF(F12>=0,"Goal Met","Below Goal")) -> Below Goal
A14: Week: Jul 06 - Jul 12
A15: Day | B15: Date | C15: Hours | D15: Daily Earnings | E15: Daily Goal | F15: Difference +/- | G15: Status
A16: Monday | B16: 7/6/2026 | E16: 175 | F16: =IF(D16="","",D16-E16) | G16: =IF(F16="","",IF(F16>=0,"Goal Met","Below Goal"))
A17: Tuesday | B17: 7/7/2026 | E17: 175 | F17: =IF(D17="","",D17-E17) | G17: =IF(F17="","",IF(F17>=0,"Goal Met","Below Goal"))
A18: Wednesday | B18: 7/8/2026 | E18: 175 | F18: =IF(D18="","",D18-E18) | G18: =IF(F18="","",IF(F18>=0,"Goal Met","Below Goal"))
A19: Thursday | B19: 7/9/2026 | E19: 175 | F19: =IF(D19="","",D19-E19) | G19: =IF(F19="","",IF(F19>=0,"Goal Met","Below Goal"))
A20: Friday | B20: 7/10/2026 | E20: 175 | F20: =IF(D20="","",D20-E20) | G20: =IF(F20="","",IF(F20>=0,"Goal Met","Below Goal"))
A21: Saturday | B21: 7/11/2026 | E21: 175 | F21: =IF(D21="","",D21-E21) | G21: =IF(F21="","",IF(F21>=0,"Goal Met","Below Goal"))
A22: Sunday | B22: 7/12/2026 | E22: 175 | F22: =IF(D22="","",D22-E22) | G22: =IF(F22="","",IF(F22>=0,"Goal Met","Below Goal"))
A23: Week Total | C23: =DOLLARFR(IFERROR(DOLLARDE(C16,60),0)+IFERROR(DOLLARDE(C17,60),0)+IFERROR(DOLLARDE(C18,60),0)+IFERROR(DOLLARDE(C19,60),0)+IFERROR(DOLLARDE(C20,60),0)+IFERROR(DOLLARDE(C21,60),0)+IFERROR(DOLLARDE(C22,60),0), 60) -> 0 | D23: =SUM(D16:D22) -> 0 | E23: =SUM(E16:E22) -> 1225 | F23: =D23-E23 -> -1225 | G23: =IF(D23="","",IF(F23>=0,"Goal Met","Below Goal")) -> Below Goal
A25: Week: Jul 13 - Jul 19
A26: Day | B26: Date | C26: Hours | D26: Daily Earnings | E26: Daily Goal | F26: Difference +/- | G26: Status
A27: Monday | B27: 7/13/2026 | E27: 175 | F27: =IF(D27="","",D27-E27) | G27: =IF(F27="","",IF(F27>=0,"Goal Met","Below Goal"))
A28: Tuesday | B28: 7/14/2026 | E28: 175 | F28: =IF(D28="","",D28-E28) | G28: =IF(F28="","",IF(F28>=0,"Goal Met","Below Goal"))
A29: Wednesday | B29: 7/15/2026 | E29: 175 | F29: =IF(D29="","",D29-E29) | G29: =IF(F29="","",IF(F29>=0,"Goal Met","Below Goal"))
A30: Thursday | B30: 7/16/2026 | E30: 175 | F30: =IF(D30="","",D30-E30) | G30: =IF(F30="","",IF(F30>=0,"Goal Met","Below Goal"))
A31: Friday | B31: 7/17/2026 | E31: 175 | F31: =IF(D31="","",D31-E31) | G31: =IF(F31="","",IF(F31>=0,"Goal Met","Below Goal"))
A32: Saturday | B32: 7/18/2026 | E32: 175 | F32: =IF(D32="","",D32-E32) | G32: =IF(F32="","",IF(F32>=0,"Goal Met","Below Goal"))
A33: Sunday | B33: 7/19/2026 | E33: 175 | F33: =IF(D33="","",D33-E33) | G33: =IF(F33="","",IF(F33>=0,"Goal Met","Below Goal"))
A34: Week Total | C34: =DOLLARFR(IFERROR(DOLLARDE(C27,60),0)+IFERROR(DOLLARDE(C28,60),0)+IFERROR(DOLLARDE(C29,60),0)+IFERROR(DOLLARDE(C30,60),0)+IFERROR(DOLLARDE(C31,60),0)+IFERROR(DOLLARDE(C32,60),0)+IFERROR(DOLLARDE(C33,60),0), 60) -> 0 | D34: =SUM(D27:D33) -> 0 | E34: =SUM(E27:E33) -> 1225 | F34: =D34-E34 -> -1225 | G34: =IF(D34="","",IF(F34>=0,"Goal Met","Below Goal")) -> Below Goal
A36: Week: Jul 20 - Jul 26
A37: Day | B37: Date | C37: Hours | D37: Daily Earnings | E37: Daily Goal | F37: Difference +/- | G37: Status
A38: Monday | B38: 7/20/2026 | E38: 175 | F38: =IF(D38="","",D38-E38) | G38: =IF(F38="","",IF(F38>=0,"Goal Met","Below Goal"))
A39: Tuesday | B39: 7/21/2026 | E39: 175 | F39: =IF(D39="","",D39-E39) | G39: =IF(F39="","",IF(F39>=0,"Goal Met","Below Goal"))
A40: Wednesday | B40: 7/22/2026 | E40: 175 | F40: =IF(D40="","",D40-E40) | G40: =IF(F40="","",IF(F40>=0,"Goal Met","Below Goal"))
A41: Thursday | B41: 7/23/2026 | E41: 175 | F41: =IF(D41="","",D41-E41) | G41: =IF(F41="","",IF(F41>=0,"Goal Met","Below Goal"))
A42: Friday | B42: 7/24/2026 | E42: 175 | F42: =IF(D42="","",D42-E42) | G42: =IF(F42="","",IF(F42>=0,"Goal Met","Below Goal"))
A43: Saturday | B43: 7/25/2026 | E43: 175 | F43: =IF(D43="","",D43-E43) | G43: =IF(F43="","",IF(F43>=0,"Goal Met","Below Goal"))
A44: Sunday | B44: 7/26/2026 | E44: 175 | F44: =IF(D44="","",D44-E44) | G44: =IF(F44="","",IF(F44>=0,"Goal Met","Below Goal"))
...

Sheet August
A1: TERRANCE MASSEY - August 2026
A3: Week: Aug 03 - Aug 09
A4: Day | B4: Date | C4: Hours | D4: Daily Earnings | E4: Daily Goal | F4: Difference +/- | G4: Status
A5: Monday | B5: 8/3/2026 | E5: 175 | F5: =IF(D5="","",D5-E5) | G5: =IF(F5="","",IF(F5>=0,"Goal Met","Below Goal"))
A6: Tuesday | B6: 8/4/2026 | E6: 175 | F6: =IF(D6="","",D6-E6) | G6: =IF(F6="","",IF(F6>=0,"Goal Met","Below Goal"))
A7: Wednesday | B7: 8/5/2026 | E7: 175 | F7: =IF(D7="","",D7-E7) | G7: =IF(F7="","",IF(F7>=0,"Goal Met","Below Goal"))
A8: Thursday | B8: 8/6/2026 | E8: 175 | F8: =IF(D8="","",D8-E8) | G8: =IF(F8="","",IF(F8>=0,"Goal Met","Below Goal"))
A9: Friday | B9: 8/7/2026 | E9: 175 | F9: =IF(D9="","",D9-E9) | G9: =IF(F9="","",IF(F9>=0,"Goal Met","Below Goal"))
A10: Saturday | B10: 8/8/2026 | E10: 175 | F10: =IF(D10="","",D10-E10) | G10: =IF(F10="","",IF(F10>=0,"Goal Met","Below Goal"))
A11: Sunday | B11: 8/9/2026 | E11: 175 | F11: =IF(D11="","",D11-E11) | G11: =IF(F11="","",IF(F11>=0,"Goal Met","Below Goal"))
A12: Week Total | C12: =DOLLARFR(IFERROR(DOLLARDE(C5,60),0)+IFERROR(DOLLARDE(C6,60),0)+IFERROR(DOLLARDE(C7,60),0)+IFERROR(DOLLARDE(C8,60),0)+IFERROR(DOLLARDE(C9,60),0)+IFERROR(DOLLARDE(C10,60),0)+IFERROR(DOLLARDE(C11,60),0), 60) -> 0 | D12: =SUM(D5:D11) -> 0 | E12: =SUM(E5:E11) -> 1225 | F12: =D12-E12 -> -1225 | G12: =IF(D12="","",IF(F12>=0,"Goal Met","Below Goal")) -> Below Goal
A14: Week: Aug 10 - Aug 16
A15: Day | B15: Date | C15: Hours | D15: Daily Earnings | E15: Daily Goal | F15: Difference +/- | G15: Status
A16: Monday | B16: 8/10/2026 | E16: 175 | F16: =IF(D16="","",D16-E16) | G16: =IF(F16="","",IF(F16>=0,"Goal Met","Below Goal"))
A17: Tuesday | B17: 8/11/2026 | E17: 175 | F17: =IF(D17="","",D17-E17) | G17: =IF(F17="","",IF(F17>=0,"Goal Met","Below Goal"))
A18: Wednesday | B18: 8/12/2026 | E18: 175 | F18: =IF(D18="","",D18-E18) | G18: =IF(F18="","",IF(F18>=0,"Goal Met","Below Goal"))
A19: Thursday | B19: 8/13/2026 | E19: 175 | F19: =IF(D19="","",D19-E19) | G19: =IF(F19="","",IF(F19>=0,"Goal Met","Below Goal"))
A20: Friday | B20: 8/14/2026 | E20: 175 | F20: =IF(D20="","",D20-E20) | G20: =IF(F20="","",IF(F20>=0,"Goal Met","Below Goal"))
A21: Saturday | B21: 8/15/2026 | E21: 175 | F21: =IF(D21="","",D21-E21) | G21: =IF(F21="","",IF(F21>=0,"Goal Met","Below Goal"))
A22: Sunday | B22: 8/16/2026 | E22: 175 | F22: =IF(D22="","",D22-E22) | G22: =IF(F22="","",IF(F22>=0,"Goal Met","Below Goal"))
A23: Week Total | C23: =DOLLARFR(IFERROR(DOLLARDE(C16,60),0)+IFERROR(DOLLARDE(C17,60),0)+IFERROR(DOLLARDE(C18,60),0)+IFERROR(DOLLARDE(C19,60),0)+IFERROR(DOLLARDE(C20,60),0)+IFERROR(DOLLARDE(C21,60),0)+IFERROR(DOLLARDE(C22,60),0), 60) -> 0 | D23: =SUM(D16:D22) -> 0 | E23: =SUM(E16:E22) -> 1225 | F23: =D23-E23 -> -1225 | G23: =IF(D23="","",IF(F23>=0,"Goal Met","Below Goal")) -> Below Goal
A25: Week: Aug 17 - Aug 23
A26: Day | B26: Date | C26: Hours | D26: Daily Earnings | E26: Daily Goal | F26: Difference +/- | G26: Status
A27: Monday | B27: 8/17/2026 | E27: 175 | F27: =IF(D27="","",D27-E27) | G27: =IF(F27="","",IF(F27>=0,"Goal Met","Below Goal"))
A28: Tuesday | B28: 8/18/2026 | E28: 175 | F28: =IF(D28="","",D28-E28) | G28: =IF(F28="","",IF(F28>=0,"Goal Met","Below Goal"))
A29: Wednesday | B29: 8/19/2026 | E29: 175 | F29: =IF(D29="","",D29-E29) | G29: =IF(F29="","",IF(F29>=0,"Goal Met","Below Goal"))
A30: Thursday | B30: 8/20/2026 | E30: 175 | F30: =IF(D30="","",D30-E30) | G30: =IF(F30="","",IF(F30>=0,"Goal Met","Below Goal"))
A31: Friday | B31: 8/21/2026 | E31: 175 | F31: =IF(D31="","",D31-E31) | G31: =IF(F31="","",IF(F31>=0,"Goal Met","Below Goal"))
A32: Saturday | B32: 8/22/2026 | E32: 175 | F32: =IF(D32="","",D32-E32) | G32: =IF(F32="","",IF(F32>=0,"Goal Met","Below Goal"))
A33: Sunday | B33: 8/23/2026 | E33: 175 | F33: =IF(D33="","",D33-E33) | G33: =IF(F33="","",IF(F33>=0,"Goal Met","Below Goal"))
A34: Week Total | C34: =DOLLARFR(IFERROR(DOLLARDE(C27,60),0)+IFERROR(DOLLARDE(C28,60),0)+IFERROR(DOLLARDE(C29,60),0)+IFERROR(DOLLARDE(C30,60),0)+IFERROR(DOLLARDE(C31,60),0)+IFERROR(DOLLARDE(C32,60),0)+IFERROR(DOLLARDE(C33,60),0), 60) -> 0 | D34: =SUM(D27:D33) -> 0 | E34: =SUM(E27:E33) -> 1225 | F34: =D34-E34 -> -1225 | G34: =IF(D34="","",IF(F34>=0,"Goal Met","Below Goal")) -> Below Goal
A36: Week: Aug 24 - Aug 30
A37: Day | B37: Date | C37: Hours | D37: Daily Earnings | E37: Daily Goal | F37: Difference +/- | G37: Status
A38: Monday | B38: 8/24/2026 | E38: 175 | F38: =IF(D38="","",D38-E38) | G38: =IF(F38="","",IF(F38>=0,"Goal Met","Below Goal"))
A39: Tuesday | B39: 8/25/2026 | E39: 175 | F39: =IF(D39="","",D39-E39) | G39: =IF(F39="","",IF(F39>=0,"Goal Met","Below Goal"))
A40: Wednesday | B40: 8/26/2026 | E40: 175 | F40: =IF(D40="","",D40-E40) | G40: =IF(F40="","",IF(F40>=0,"Goal Met","Below Goal"))
A41: Thursday | B41: 8/27/2026 | E41: 175 | F41: =IF(D41="","",D41-E41) | G41: =IF(F41="","",IF(F41>=0,"Goal Met","Below Goal"))
A42: Friday | B42: 8/28/2026 | E42: 175 | F42: =IF(D42="","",D42-E42) | G42: =IF(F42="","",IF(F42>=0,"Goal Met","Below Goal"))
A43: Saturday | B43: 8/29/2026 | E43: 175 | F43: =IF(D43="","",D43-E43) | G43: =IF(F43="","",IF(F43>=0,"Goal Met","Below Goal"))
A44: Sunday | B44: 8/30/2026 | E44: 175 | F44: =IF(D44="","",D44-E44) | G44: =IF(F44="","",IF(F44>=0,"Goal Met","Below Goal"))
...

Sheet September
A1: TERRANCE MASSEY - September 2026
A3: Week: Aug 31 - Sep 06
A4: Day | B4: Date | C4: Hours | D4: Daily Earnings | E4: Daily Goal | F4: Difference +/- | G4: Status
A5: Monday | B5: 8/31/2026 | E5: 175 | F5: =IF(D5="","",D5-E5) | G5: =IF(F5="","",IF(F5>=0,"Goal Met","Below Goal"))
A6: Tuesday | B6: 9/1/2026 | E6: 175 | F6: =IF(D6="","",D6-E6) | G6: =IF(F6="","",IF(F6>=0,"Goal Met","Below Goal"))
A7: Wednesday | B7: 9/2/2026 | E7: 175 | F7: =IF(D7="","",D7-E7) | G7: =IF(F7="","",IF(F7>=0,"Goal Met","Below Goal"))
A8: Thursday | B8: 9/3/2026 | E8: 175 | F8: =IF(D8="","",D8-E8) | G8: =IF(F8="","",IF(F8>=0,"Goal Met","Below Goal"))
A9: Friday | B9: 9/4/2026 | E9: 175 | F9: =IF(D9="","",D9-E9) | G9: =IF(F9="","",IF(F9>=0,"Goal Met","Below Goal"))
A10: Saturday | B10: 9/5/2026 | E10: 175 | F10: =IF(D10="","",D10-E10) | G10: =IF(F10="","",IF(F10>=0,"Goal Met","Below Goal"))
A11: Sunday | B11: 9/6/2026 | E11: 175 | F11: =IF(D11="","",D11-E11) | G11: =IF(F11="","",IF(F11>=0,"Goal Met","Below Goal"))
A12: Week Total | C12: =DOLLARFR(IFERROR(DOLLARDE(C5,60),0)+IFERROR(DOLLARDE(C6,60),0)+IFERROR(DOLLARDE(C7,60),0)+IFERROR(DOLLARDE(C8,60),0)+IFERROR(DOLLARDE(C9,60),0)+IFERROR(DOLLARDE(C10,60),0)+IFERROR(DOLLARDE(C11,60),0), 60) -> 0 | D12: =SUM(D5:D11) -> 0 | E12: =SUM(E5:E11) -> 1225 | F12: =D12-E12 -> -1225 | G12: =IF(D12="","",IF(F12>=0,"Goal Met","Below Goal")) -> Below Goal
A14: Week: Sep 07 - Sep 13
A15: Day | B15: Date | C15: Hours | D15: Daily Earnings | E15: Daily Goal | F15: Difference +/- | G15: Status
A16: Monday | B16: 9/7/2026 | E16: 175 | F16: =IF(D16="","",D16-E16) | G16: =IF(F16="","",IF(F16>=0,"Goal Met","Below Goal"))
A17: Tuesday | B17: 9/8/2026 | E17: 175 | F17: =IF(D17="","",D17-E17) | G17: =IF(F17="","",IF(F17>=0,"Goal Met","Below Goal"))
A18: Wednesday | B18: 9/9/2026 | E18: 175 | F18: =IF(D18="","",D18-E18) | G18: =IF(F18="","",IF(F18>=0,"Goal Met","Below Goal"))
A19: Thursday | B19: 9/10/2026 | E19: 175 | F19: =IF(D19="","",D19-E19) | G19: =IF(F19="","",IF(F19>=0,"Goal Met","Below Goal"))
A20: Friday | B20: 9/11/2026 | E20: 175 | F20: =IF(D20="","",D20-E20) | G20: =IF(F20="","",IF(F20>=0,"Goal Met","Below Goal"))
A21: Saturday | B21: 9/12/2026 | E21: 175 | F21: =IF(D21="","",D21-E21) | G21: =IF(F21="","",IF(F21>=0,"Goal Met","Below Goal"))
A22: Sunday | B22: 9/13/2026 | E22: 175 | F22: =IF(D22="","",D22-E22) | G22: =IF(F22="","",IF(F22>=0,"Goal Met","Below Goal"))
A23: Week Total | C23: =DOLLARFR(IFERROR(DOLLARDE(C16,60),0)+IFERROR(DOLLARDE(C17,60),0)+IFERROR(DOLLARDE(C18,60),0)+IFERROR(DOLLARDE(C19,60),0)+IFERROR(DOLLARDE(C20,60),0)+IFERROR(DOLLARDE(C21,60),0)+IFERROR(DOLLARDE(C22,60),0), 60) -> 0 | D23: =SUM(D16:D22) -> 0 | E23: =SUM(E16:E22) -> 1225 | F23: =D23-E23 -> -1225 | G23: =IF(D23="","",IF(F23>=0,"Goal Met","Below Goal")) -> Below Goal
A25: Week: Sep 14 - Sep 20
A26: Day | B26: Date | C26: Hours | D26: Daily Earnings | E26: Daily Goal | F26: Difference +/- | G26: Status
A27: Monday | B27: 9/14/2026 | E27: 175 | F27: =IF(D27="","",D27-E27) | G27: =IF(F27="","",IF(F27>=0,"Goal Met","Below Goal"))
A28: Tuesday | B28: 9/15/2026 | E28: 175 | F28: =IF(D28="","",D28-E28) | G28: =IF(F28="","",IF(F28>=0,"Goal Met","Below Goal"))
A29: Wednesday | B29: 9/16/2026 | E29: 175 | F29: =IF(D29="","",D29-E29) | G29: =IF(F29="","",IF(F29>=0,"Goal Met","Below Goal"))
A30: Thursday | B30: 9/17/2026 | E30: 175 | F30: =IF(D30="","",D30-E30) | G30: =IF(F30="","",IF(F30>=0,"Goal Met","Below Goal"))
A31: Friday | B31: 9/18/2026 | E31: 175 | F31: =IF(D31="","",D31-E31) | G31: =IF(F31="","",IF(F31>=0,"Goal Met","Below Goal"))
A32: Saturday | B32: 9/19/2026 | E32: 175 | F32: =IF(D32="","",D32-E32) | G32: =IF(F32="","",IF(F32>=0,"Goal Met","Below Goal"))
A33: Sunday | B33: 9/20/2026 | E33: 175 | F33: =IF(D33="","",D33-E33) | G33: =IF(F33="","",IF(F33>=0,"Goal Met","Below Goal"))
A34: Week Total | C34: =DOLLARFR(IFERROR(DOLLARDE(C27,60),0)+IFERROR(DOLLARDE(C28,60),0)+IFERROR(DOLLARDE(C29,60),0)+IFERROR(DOLLARDE(C30,60),0)+IFERROR(DOLLARDE(C31,60),0)+IFERROR(DOLLARDE(C32,60),0)+IFERROR(DOLLARDE(C33,60),0), 60) -> 0 | D34: =SUM(D27:D33) -> 0 | E34: =SUM(E27:E33) -> 1225 | F34: =D34-E34 -> -1225 | G34: =IF(D34="","",IF(F34>=0,"Goal Met","Below Goal")) -> Below Goal
A36: Week: Sep 21 - Sep 27
A37: Day | B37: Date | C37: Hours | D37: Daily Earnings | E37: Daily Goal | F37: Difference +/- | G37: Status
A38: Monday | B38: 9/21/2026 | E38: 175 | F38: =IF(D38="","",D38-E38) | G38: =IF(F38="","",IF(F38>=0,"Goal Met","Below Goal"))
A39: Tuesday | B39: 9/22/2026 | E39: 175 | F39: =IF(D39="","",D39-E39) | G39: =IF(F39="","",IF(F39>=0,"Goal Met","Below Goal"))
A40: Wednesday | B40: 9/23/2026 | E40: 175 | F40: =IF(D40="","",D40-E40) | G40: =IF(F40="","",IF(F40>=0,"Goal Met","Below Goal"))
A41: Thursday | B41: 9/24/2026 | E41: 175 | F41: =IF(D41="","",D41-E41) | G41: =IF(F41="","",IF(F41>=0,"Goal Met","Below Goal"))
A42: Friday | B42: 9/25/2026 | E42: 175 | F42: =IF(D42="","",D42-E42) | G42: =IF(F42="","",IF(F42>=0,"Goal Met","Below Goal"))
A43: Saturday | B43: 9/26/2026 | E43: 175 | F43: =IF(D43="","",D43-E43) | G43: =IF(F43="","",IF(F43>=0,"Goal Met","Below Goal"))
A44: Sunday | B44: 9/27/2026 | E44: 175 | F44: =IF(D44="","",D44-E44) | G44: =IF(F44="","",IF(F44>=0,"Goal Met","Below Goal"))
...

Sheet October
A1: TERRANCE MASSEY - October 2026
A3: Week: Oct 05 - Oct 11
A4: Day | B4: Date | C4: Hours | D4: Daily Earnings | E4: Daily Goal | F4: Difference +/- | G4: Status
A5: Monday | B5: 10/5/2026 | E5: 175 | F5: =IF(D5="","",D5-E5) | G5: =IF(F5="","",IF(F5>=0,"Goal Met","Below Goal"))
A6: Tuesday | B6: 10/6/2026 | E6: 175 | F6: =IF(D6="","",D6-E6) | G6: =IF(F6="","",IF(F6>=0,"Goal Met","Below Goal"))
A7: Wednesday | B7: 10/7/2026 | E7: 175 | F7: =IF(D7="","",D7-E7) | G7: =IF(F7="","",IF(F7>=0,"Goal Met","Below Goal"))
A8: Thursday | B8: 10/8/2026 | E8: 175 | F8: =IF(D8="","",D8-E8) | G8: =IF(F8="","",IF(F8>=0,"Goal Met","Below Goal"))
A9: Friday | B9: 10/9/2026 | E9: 175 | F9: =IF(D9="","",D9-E9) | G9: =IF(F9="","",IF(F9>=0,"Goal Met","Below Goal"))
A10: Saturday | B10: 10/10/2026 | E10: 175 | F10: =IF(D10="","",D10-E10) | G10: =IF(F10="","",IF(F10>=0,"Goal Met","Below Goal"))
A11: Sunday | B11: 10/11/2026 | E11: 175 | F11: =IF(D11="","",D11-E11) | G11: =IF(F11="","",IF(F11>=0,"Goal Met","Below Goal"))
A12: Week Total | C12: =DOLLARFR(IFERROR(DOLLARDE(C5,60),0)+IFERROR(DOLLARDE(C6,60),0)+IFERROR(DOLLARDE(C7,60),0)+IFERROR(DOLLARDE(C8,60),0)+IFERROR(DOLLARDE(C9,60),0)+IFERROR(DOLLARDE(C10,60),0)+IFERROR(DOLLARDE(C11,60),0), 60) -> 0 | D12: =SUM(D5:D11) -> 0 | E12: =SUM(E5:E11) -> 1225 | F12: =D12-E12 -> -1225 | G12: =IF(D12="","",IF(F12>=0,"Goal Met","Below Goal")) -> Below Goal
A14: Week: Oct 12 - Oct 18
A15: Day | B15: Date | C15: Hours | D15: Daily Earnings | E15: Daily Goal | F15: Difference +/- | G15: Status
A16: Monday | B16: 10/12/2026 | E16: 175 | F16: =IF(D16="","",D16-E16) | G16: =IF(F16="","",IF(F16>=0,"Goal Met","Below Goal"))
A17: Tuesday | B17: 10/13/2026 | E17: 175 | F17: =IF(D17="","",D17-E17) | G17: =IF(F17="","",IF(F17>=0,"Goal Met","Below Goal"))
A18: Wednesday | B18: 10/14/2026 | E18: 175 | F18: =IF(D18="","",D18-E18) | G18: =IF(F18="","",IF(F18>=0,"Goal Met","Below Goal"))
A19: Thursday | B19: 10/15/2026 | E19: 175 | F19: =IF(D19="","",D19-E19) | G19: =IF(F19="","",IF(F19>=0,"Goal Met","Below Goal"))
A20: Friday | B20: 10/16/2026 | E20: 175 | F20: =IF(D20="","",D20-E20) | G20: =IF(F20="","",IF(F20>=0,"Goal Met","Below Goal"))
A21: Saturday | B21: 10/17/2026 | E21: 175 | F21: =IF(D21="","",D21-E21) | G21: =IF(F21="","",IF(F21>=0,"Goal Met","Below Goal"))
A22: Sunday | B22: 10/18/2026 | E22: 175 | F22: =IF(D22="","",D22-E22) | G22: =IF(F22="","",IF(F22>=0,"Goal Met","Below Goal"))
A23: Week Total | C23: =DOLLARFR(IFERROR(DOLLARDE(C16,60),0)+IFERROR(DOLLARDE(C17,60),0)+IFERROR(DOLLARDE(C18,60),0)+IFERROR(DOLLARDE(C19,60),0)+IFERROR(DOLLARDE(C20,60),0)+IFERROR(DOLLARDE(C21,60),0)+IFERROR(DOLLARDE(C22,60),0), 60) -> 0 | D23: =SUM(D16:D22) -> 0 | E23: =SUM(E16:E22) -> 1225 | F23: =D23-E23 -> -1225 | G23: =IF(D23="","",IF(F23>=0,"Goal Met","Below Goal")) -> Below Goal
A25: Week: Oct 19 - Oct 25
A26: Day | B26: Date | C26: Hours | D26: Daily Earnings | E26: Daily Goal | F26: Difference +/- | G26: Status
A27: Monday | B27: 10/19/2026 | E27: 175 | F27: =IF(D27="","",D27-E27) | G27: =IF(F27="","",IF(F27>=0,"Goal Met","Below Goal"))
A28: Tuesday | B28: 10/20/2026 | E28: 175 | F28: =IF(D28="","",D28-E28) | G28: =IF(F28="","",IF(F28>=0,"Goal Met","Below Goal"))
A29: Wednesday | B29: 10/21/2026 | E29: 175 | F29: =IF(D29="","",D29-E29) | G29: =IF(F29="","",IF(F29>=0,"Goal Met","Below Goal"))
A30: Thursday | B30: 10/22/2026 | E30: 175 | F30: =IF(D30="","",D30-E30) | G30: =IF(F30="","",IF(F30>=0,"Goal Met","Below Goal"))
A31: Friday | B31: 10/23/2026 | E31: 175 | F31: =IF(D31="","",D31-E31) | G31: =IF(F31="","",IF(F31>=0,"Goal Met","Below Goal"))
A32: Saturday | B32: 10/24/2026 | E32: 175 | F32: =IF(D32="","",D32-E32) | G32: =IF(F32="","",IF(F32>=0,"Goal Met","Below Goal"))
A33: Sunday | B33: 10/25/2026 | E33: 175 | F33: =IF(D33="","",D33-E33) | G33: =IF(F33="","",IF(F33>=0,"Goal Met","Below Goal"))
A34: Week Total | C34: =DOLLARFR(IFERROR(DOLLARDE(C27,60),0)+IFERROR(DOLLARDE(C28,60),0)+IFERROR(DOLLARDE(C29,60),0)+IFERROR(DOLLARDE(C30,60),0)+IFERROR(DOLLARDE(C31,60),0)+IFERROR(DOLLARDE(C32,60),0)+IFERROR(DOLLARDE(C33,60),0), 60) -> 0 | D34: =SUM(D27:D33) -> 0 | E34: =SUM(E27:E33) -> 1225 | F34: =D34-E34 -> -1225 | G34: =IF(D34="","",IF(F34>=0,"Goal Met","Below Goal")) -> Below Goal
A36: Week: Oct 26 - Nov 01
A37: Day | B37: Date | C37: Hours | D37: Daily Earnings | E37: Daily Goal | F37: Difference +/- | G37: Status
A38: Monday | B38: 10/26/2026 | E38: 175 | F38: =IF(D38="","",D38-E38) | G38: =IF(F38="","",IF(F38>=0,"Goal Met","Below Goal"))
A39: Tuesday | B39: 10/27/2026 | E39: 175 | F39: =IF(D39="","",D39-E39) | G39: =IF(F39="","",IF(F39>=0,"Goal Met","Below Goal"))
A40: Wednesday | B40: 10/28/2026 | E40: 175 | F40: =IF(D40="","",D40-E40) | G40: =IF(F40="","",IF(F40>=0,"Goal Met","Below Goal"))
A41: Thursday | B41: 10/29/2026 | E41: 175 | F41: =IF(D41="","",D41-E41) | G41: =IF(F41="","",IF(F41>=0,"Goal Met","Below Goal"))
A42: Friday | B42: 10/30/2026 | E42: 175 | F42: =IF(D42="","",D42-E42) | G42: =IF(F42="","",IF(F42>=0,"Goal Met","Below Goal"))
A43: Saturday | B43: 10/31/2026 | E43: 175 | F43: =IF(D43="","",D43-E43) | G43: =IF(F43="","",IF(F43>=0,"Goal Met","Below Goal"))
A44: Sunday | B44: 11/1/2026 | E44: 175 | F44: =IF(D44="","",D44-E44) | G44: =IF(F44="","",IF(F44>=0,"Goal Met","Below Goal"))
...

Sheet November
A1: TERRANCE MASSEY - November 2026
A3: Week: Nov 02 - Nov 08
A4: Day | B4: Date | C4: Hours | D4: Daily Earnings | E4: Daily Goal | F4: Difference +/- | G4: Status
A5: Monday | B5: 11/2/2026 | E5: 175 | F5: =IF(D5="","",D5-E5) | G5: =IF(F5="","",IF(F5>=0,"Goal Met","Below Goal"))
A6: Tuesday | B6: 11/3/2026 | E6: 175 | F6: =IF(D6="","",D6-E6) | G6: =IF(F6="","",IF(F6>=0,"Goal Met","Below Goal"))
A7: Wednesday | B7: 11/4/2026 | E7: 175 | F7: =IF(D7="","",D7-E7) | G7: =IF(F7="","",IF(F7>=0,"Goal Met","Below Goal"))
A8: Thursday | B8: 11/5/2026 | E8: 175 | F8: =IF(D8="","",D8-E8) | G8: =IF(F8="","",IF(F8>=0,"Goal Met","Below Goal"))
A9: Friday | B9: 11/6/2026 | E9: 175 | F9: =IF(D9="","",D9-E9) | G9: =IF(F9="","",IF(F9>=0,"Goal Met","Below Goal"))
A10: Saturday | B10: 11/7/2026 | E10: 175 | F10: =IF(D10="","",D10-E10) | G10: =IF(F10="","",IF(F10>=0,"Goal Met","Below Goal"))
A11: Sunday | B11: 11/8/2026 | E11: 175 | F11: =IF(D11="","",D11-E11) | G11: =IF(F11="","",IF(F11>=0,"Goal Met","Below Goal"))
A12: Week Total | C12: =DOLLARFR(IFERROR(DOLLARDE(C5,60),0)+IFERROR(DOLLARDE(C6,60),0)+IFERROR(DOLLARDE(C7,60),0)+IFERROR(DOLLARDE(C8,60),0)+IFERROR(DOLLARDE(C9,60),0)+IFERROR(DOLLARDE(C10,60),0)+IFERROR(DOLLARDE(C11,60),0), 60) -> 0 | D12: =SUM(D5:D11) -> 0 | E12: =SUM(E5:E11) -> 1225 | F12: =D12-E12 -> -1225 | G12: =IF(D12="","",IF(F12>=0,"Goal Met","Below Goal")) -> Below Goal
A14: Week: Nov 09 - Nov 15
A15: Day | B15: Date | C15: Hours | D15: Daily Earnings | E15: Daily Goal | F15: Difference +/- | G15: Status
A16: Monday | B16: 11/9/2026 | E16: 175 | F16: =IF(D16="","",D16-E16) | G16: =IF(F16="","",IF(F16>=0,"Goal Met","Below Goal"))
A17: Tuesday | B17: 11/10/2026 | E17: 175 | F17: =IF(D17="","",D17-E17) | G17: =IF(F17="","",IF(F17>=0,"Goal Met","Below Goal"))
A18: Wednesday | B18: 11/11/2026 | E18: 175 | F18: =IF(D18="","",D18-E18) | G18: =IF(F18="","",IF(F18>=0,"Goal Met","Below Goal"))
A19: Thursday | B19: 11/12/2026 | E19: 175 | F19: =IF(D19="","",D19-E19) | G19: =IF(F19="","",IF(F19>=0,"Goal Met","Below Goal"))
A20: Friday | B20: 11/13/2026 | E20: 175 | F20: =IF(D20="","",D20-E20) | G20: =IF(F20="","",IF(F20>=0,"Goal Met","Below Goal"))
A21: Saturday | B21: 11/14/2026 | E21: 175 | F21: =IF(D21="","",D21-E21) | G21: =IF(F21="","",IF(F21>=0,"Goal Met","Below Goal"))
A22: Sunday | B22: 11/15/2026 | E22: 175 | F22: =IF(D22="","",D22-E22) | G22: =IF(F22="","",IF(F22>=0,"Goal Met","Below Goal"))
A23: Week Total | C23: =DOLLARFR(IFERROR(DOLLARDE(C16,60),0)+IFERROR(DOLLARDE(C17,60),0)+IFERROR(DOLLARDE(C18,60),0)+IFERROR(DOLLARDE(C19,60),0)+IFERROR(DOLLARDE(C20,60),0)+IFERROR(DOLLARDE(C21,60),0)+IFERROR(DOLLARDE(C22,60),0), 60) -> 0 | D23: =SUM(D16:D22) -> 0 | E23: =SUM(E16:E22) -> 1225 | F23: =D23-E23 -> -1225 | G23: =IF(D23="","",IF(F23>=0,"Goal Met","Below Goal")) -> Below Goal
A25: Week: Nov 16 - Nov 22
A26: Day | B26: Date | C26: Hours | D26: Daily Earnings | E26: Daily Goal | F26: Difference +/- | G26: Status
A27: Monday | B27: 11/16/2026 | E27: 175 | F27: =IF(D27="","",D27-E27) | G27: =IF(F27="","",IF(F27>=0,"Goal Met","Below Goal"))
A28: Tuesday | B28: 11/17/2026 | E28: 175 | F28: =IF(D28="","",D28-E28) | G28: =IF(F28="","",IF(F28>=0,"Goal Met","Below Goal"))
A29: Wednesday | B29: 11/18/2026 | E29: 175 | F29: =IF(D29="","",D29-E29) | G29: =IF(F29="","",IF(F29>=0,"Goal Met","Below Goal"))
A30: Thursday | B30: 11/19/2026 | E30: 175 | F30: =IF(D30="","",D30-E30) | G30: =IF(F30="","",IF(F30>=0,"Goal Met","Below Goal"))
A31: Friday | B31: 11/20/2026 | E31: 175 | F31: =IF(D31="","",D31-E31) | G31: =IF(F31="","",IF(F31>=0,"Goal Met","Below Goal"))
A32: Saturday | B32: 11/21/2026 | E32: 175 | F32: =IF(D32="","",D32-E32) | G32: =IF(F32="","",IF(F32>=0,"Goal Met","Below Goal"))
A33: Sunday | B33: 11/22/2026 | E33: 175 | F33: =IF(D33="","",D33-E33) | G33: =IF(F33="","",IF(F33>=0,"Goal Met","Below Goal"))
A34: Week Total | C34: =DOLLARFR(IFERROR(DOLLARDE(C27,60),0)+IFERROR(DOLLARDE(C28,60),0)+IFERROR(DOLLARDE(C29,60),0)+IFERROR(DOLLARDE(C30,60),0)+IFERROR(DOLLARDE(C31,60),0)+IFERROR(DOLLARDE(C32,60),0)+IFERROR(DOLLARDE(C33,60),0), 60) -> 0 | D34: =SUM(D27:D33) -> 0 | E34: =SUM(E27:E33) -> 1225 | F34: =D34-E34 -> -1225 | G34: =IF(D34="","",IF(F34>=0,"Goal Met","Below Goal")) -> Below Goal
A36: Week: Nov 23 - Nov 29
A37: Day | B37: Date | C37: Hours | D37: Daily Earnings | E37: Daily Goal | F37: Difference +/- | G37: Status
